Workbook
Name ESTACOES: _xlfn.anchorarray('Cadastro Estacoes'!$AZ$1)
Name ItemCadastrado: CadastroItens[ITEM]
Name PROJETO: _xlfn.anchorarray('Cadastro Estacoes'!$BA$1)
Name TAB_FALHA: Tabela_FALHA[FALHA]
Name TAB_ITEM: Tabela_ITEM[ITEM]
Name TAB_MOTIVO: Tabela_MOTIVO[MOTIVO]
Name ItemCadastrado: CadastroItens[ITEM]
Name TAB_FALHA: Tabela_FALHA[FALHA]
Name TAB_ITEM: Tabela_ITEM[ITEM]
Name TAB_MOTIVO: Tabela_MOTIVO[MOTIVO]
Name ItemCadastrado: CadastroItens[ITEM]
Name TAB_FALHA: Tabela_FALHA[FALHA]
Name TAB_ITEM: Tabela_ITEM[ITEM]
Name TAB_MOTIVO: Tabela_MOTIVO[MOTIVO]
Name ItemCadastrado: CadastroItens[ITEM]
Name TAB_FALHA: Tabela_FALHA[FALHA]
Name TAB_ITEM: Tabela_ITEM[ITEM]
Name TAB_MOTIVO: Tabela_MOTIVO[MOTIVO]
Name ItemCadastrado: CadastroItens[ITEM]
Name TAB_FALHA: Tabela_FALHA[FALHA]
Name TAB_ITEM: Tabela_ITEM[ITEM]
Name TAB_MOTIVO: Tabela_MOTIVO[MOTIVO]
Name ItemCadastrado: CadastroItens[ITEM]
Name TAB_FALHA: Tabela_FALHA[FALHA]
Name TAB_ITEM: Tabela_ITEM[ITEM]
Name TAB_MOTIVO: Tabela_MOTIVO[MOTIVO]
Name TAB_FALHA: Tabela_FALHA[FALHA]
Name TAB_ITEM: Tabela_ITEM[ITEM]
Name TAB_MOTIVO: Tabela_MOTIVO[MOTIVO]
Name TAB_FALHA: Tabela_FALHA[FALHA]
Name TAB_ITEM: Tabela_ITEM[ITEM]
Name TAB_MOTIVO: Tabela_MOTIVO[MOTIVO]
Name TAB_FALHA: Tabela_FALHA[FALHA]
Name TAB_ITEM: Tabela_ITEM[ITEM]
Name TAB_MOTIVO: Tabela_MOTIVO[MOTIVO]
Name TAB_FALHA: Tabela_FALHA[FALHA]
Name TAB_ITEM: Tabela_ITEM[ITEM]
Name TAB_MOTIVO: Tabela_MOTIVO[MOTIVO]
Name TAB_FALHA: Tabela_FALHA[FALHA]
Name TAB_ITEM: Tabela_ITEM[ITEM]
Name TAB_MOTIVO: Tabela_MOTIVO[MOTIVO]
Name TAB_FALHA: Tabela_FALHA[FALHA]
Name TAB_ITEM: Tabela_ITEM[ITEM]
Name TAB_MOTIVO: Tabela_MOTIVO[MOTIVO]
Name TAB_FALHA: Tabela_FALHA[FALHA]
Name TAB_ITEM: Tabela_ITEM[ITEM]
Name TAB_MOTIVO: Tabela_MOTIVO[MOTIVO]
Name TAB_FALHA: Tabela_FALHA[FALHA]
Name TAB_ITEM: Tabela_ITEM[ITEM]
Name TAB_MOTIVO: Tabela_MOTIVO[MOTIVO]
Name TAB_FALHA: Tabela_FALHA[FALHA]
Name TAB_ITEM: Tabela_ITEM[ITEM]
Name TAB_MOTIVO: Tabela_MOTIVO[MOTIVO]
Name resp: RespStatusEstacoes!$A$1:$A$21

Sheet RespStatusEstacoes
A1: LFF | B1: Luiz Fernando Campos Furlan | C1: fernando@hidromares.com.br | E1: CO
A2: RS | B2: Rodrigo Saggiomo | C2: rodrigo@hidromares.com.br | E2: Qualidade
A3: ADC | B3: Alexandre De Caroli | C3: alexandre@hidromares.com.br | E3: DT
A4: GCA | B4: Gabriel Paschoal | C4: gabriel@hidromares.com.br | E4: DC
A5: FMS | B5: Francisco Moreira Silvério | C5: francisco@hidromares.com.br | E5: CO
A6: LSP | B6: Lucas Pagano | C6: lucas@hidromares.com.br | E6: O
A7: FPM | B7: Felipe Porfírio Marques | C7: felipe.marques@hidromares.com.br | E7: O
A8: EMD | B8: Eliezer Matias Lima dos Santos Dias | C8: eliezer@hidromares.com.br | E8: T
A9: EJC | B9: Edmar de Jesus Cardoso | C9: edmar@hidromares.com.br | E9: O
A10: DSS | B10: Diego de Sena Santos | C10: diego@hidromares.com.br | E10: A
A11: RO | B11: Renato Oliveira | C11: renato@hidromares.com.br | E11: O
A12: VCP | B12: Vanessa | C12: vanessa@hidromares.com.br | E12: O
... A20: LHC | B20: Luiz Henrique dos Santos Cruz | C20: luiz.cruz@hidromares.com.br | E20: A
A23: Feito | B23: Alta
A24: A fazer | B24: Média
A25: Fazendo | B25: Baixa

Sheet Planilha1
A2: {=_xlws.FILTER(Pendencias!A:Q,Pendencias!L:L="ADC","")} -> #NAME?

Sheet Pendencias Feitas Backup
A2: P0008 | B2: HMCSNB22 | C2: Levar e instalar RNS para nivelamento | D2: 1 | E2: 43434 | F2: =IF(Tabela18[[#This Row],[Estações]]="HMOFICINA","VMS",IFERROR(VLOOKUP(B2,'Cadastro Estacoes'!$A$2:$Z$201,26,0),"")) -> #ERROR! | G2: Feito | I2: RN | J2: 1 | K2: EMD | L2: ESS | M2: 43410 | N2: C | O2: 43410 | P2: =IFERROR(VLOOKUP(B2,'Cadastro Estacoes'!$A:$B,2,0),"") -> SISMO®CSN
A3: P0021 | B3: HMPDMDOLFIM08 | C3: Realizar um dia de lançamento de derivadores | D3: 2 | E3: 11/10/2019 | F3: =IF(Tabela18[[#This Row],[Estações]]="HMOFICINA","VMS",IFERROR(VLOOKUP(B3,'Cadastro Estacoes'!$A$2:$Z$201,26,0),"")) -> #ERROR! | G3: Feito | H3: Separar um dia do campo apenas para isso | I3: 2 derivadores; 2 GPS reservas | K3: LSP | L3: FMS | M3: 30/04/2019 | N3: C | O3: 43956 | P3: =IFERROR(VLOOKUP(B3,'Cadastro Estacoes'!$A:$B,2,0),"") -> SISMO®VALEPDM
A4: P0024 | B4: HMPSEPIER | C4: Colocar tampa no furo do alçapão do tubulão | D4: 2 | E4: 20/03/2020 | F4: =IF(Tabela18[[#This Row],[Estações]]="HMOFICINA","VMS",IFERROR(VLOOKUP(B4,'Cadastro Estacoes'!$A$2:$Z$201,26,0),"")) -> #ERROR! | G4: Feito | H4: esta pendeencia está atrelada à P0671 | K4: EMD | L4: EJC | M4: 17/01/2020 | N4: C | O4: 44206 | P4: =IFERROR(VLOOKUP(B4,'Cadastro Estacoes'!$A:$B,2,0),"") -> SISMO®PSE
A5: P0025 | B5: HMTJMONTANHA | C5: Realizar um dia de lançamento de derivadores | D5: 1 | E5: 31/03/2020 | F5: =IF(Tabela18[[#This Row],[Estações]]="HMOFICINA","VMS",IFERROR(VLOOKUP(B5,'Cadastro Estacoes'!$A$2:$Z$201,26,0),"")) -> #ERROR! | G5: Feito | H5: Separar um dia do campo apenas para isso | I5: 2 derivadores; 2 GPS reservas | L5: FMS | M5: 30/04/2019 | N5: C | P5: =IFERROR(VLOOKUP(B5,'Cadastro Estacoes'!$A:$B,2,0),"") -> SISMO®TAPAJOS
A6: P0029 | B6: HMTJTORRE1 | C6: Instalar abracadeira de inox para prender tubo do young na madeira | D6: 0 | E6: 24/05/2020 | F6: =IF(Tabela18[[#This Row],[Estações]]="HMOFICINA","VMS",IFERROR(VLOOKUP(B6,'Cadastro Estacoes'!$A$2:$Z$201,26,0),"")) -> #ERROR! | G6: Feito | H6: Abraçadeira de inox 64-83 é pequena | K6: CCL | L6: ESS | M6: 13/05/2019 | N6: C | O6: 44110 | P6: =IFERROR(VLOOKUP(B6,'Cadastro Estacoes'!$A:$B,2,0),"") -> SISMO®TAPAJOS
A7: P0055 | B7: HMQIGUARAS | C7: Trocar a régua de maré | D7: 3 | E7: 29/10/2019 | F7: =IF(Tabela18[[#This Row],[Estações]]="HMOFICINA","VMS",IFERROR(VLOOKUP(B7,'Cadastro Estacoes'!$A$2:$Z$201,26,0),"")) -> #ERROR! | G7: Feito | H7: Estão faltando 4 lances de régua | K7: FPM | L7: VCP | M7: 30/07/2019 | N7: C | O7: 43767 | P7: =IFERROR(VLOOKUP(B7,'Cadastro Estacoes'!$A:$B,2,0),"") -> SISMO®QUIRIRI
A8: P0059 | B8: HMPSEPIER | C8: Fazer lançamentos de CastAway próximo ao sensor CT, 4 antes e 4 após a limpeza no sensor, com intervalos de 5 minutos entre os lançamentos | D8: 1 | E8: Permanente | F8: =IF(Tabela18[[#This Row],[Estações]]="HMOFICINA","VMS",IFERROR(VLOOKUP(B8,'Cadastro Estacoes'!$A$2:$Z$201,26,0),"")) -> #ERROR! | G8: Feito | I8: CastAway | K8: EMD | L8: VCP | M8: 30/07/2019 | N8: C | O8: 43900 | P8: =IFERROR(VLOOKUP(B8,'Cadastro Estacoes'!$A:$B,2,0),"") -> SISMO®PSE
A9: P0108 | B9: HMPPMIRA | C9: fazer suporte para caixa de bateria | D9: 1 | E9: 20/10/2019 | F9: =IF(Tabela18[[#This Row],[Estações]]="HMOFICINA","VMS",IFERROR(VLOOKUP(B9,'Cadastro Estacoes'!$A$2:$Z$201,26,0),"")) -> #ERROR! | G9: Feito | H9: está sobreposta sobre as baterias dos eqp. praticagem | I9: parafusos/buchas/arroelas/porcas | K9: FPM | L9: JBM | M9: 16/09/2019 | N9: O | O9: 16/09/2019 | P9: =IFERROR(VLOOKUP(B9,'Cadastro Estacoes'!$A:$B,2,0),"") -> SISMO®PARANAGUAPILOTS
A10: P0109 | B10: HMCAPIER | C10: Fazer uma regua de mare para substituir a danificada | D10: 0 | E10: 20/10/2019 | F10: =IF(Tabela18[[#This Row],[Estações]]="HMOFICINA","VMS",IFERROR(VLOOKUP(B10,'Cadastro Estacoes'!$A$2:$Z$201,26,0),"")) -> #ERROR! | G10: Feito | K10: FPM | L10: JBM | M10: 16/09/2019 | N10: O | O10: 16/09/2019 | P10: =IFERROR(VLOOKUP(B10,'Cadastro Estacoes'!$A:$B,2,0),"") -> SISMO®CATTALINI
A11: P0112 | B11: HMPDMDOLFIM15 | C11: Levar Cracha Vale | D11: 0 | E11: Permanente | F11: =IF(Tabela18[[#This Row],[Estações]]="HMOFICINA","VMS",IFERROR(VLOOKUP(B11,'Cadastro Estacoes'!$A$2:$Z$201,26,0),"")) -> #ERROR! | G11: Feito | I11: Crachá | K11: LSP | L11: LSP | M11: 16/09/2019 | N11: C | O11: 29/11/2019 | P11: =IFERROR(VLOOKUP(B11,'Cadastro Estacoes'!$A:$B,2,0),"") -> SISMO®VALEPDM
A12: P0113 | B12: HMPDMDOLFIM08 | C12: Adaptar APR para manobra a ser realizada. | D12: 0 | E12: Permanente | F12: =IF(Tabela18[[#This Row],[Estações]]="HMOFICINA","VMS",IFERROR(VLOOKUP(B12,'Cadastro Estacoes'!$A$2:$Z$201,26,0),"")) -> #ERROR! | G12: Feito | I12: APR preenchida | K12: LSP | L12: LSP | M12: 16/09/2019 | N12: O | O12: 24/01/2020 | P12: =IFERROR(VLOOKUP(B12,'Cadastro Estacoes'!$A:$B,2,0),"") -> SISMO®VALEPDM
A13: P0114 | B13: HMPDMDOLFIM08 | C13: Levar Cracha Vale | D13: 0 | E13: Permanente | F13: =IF(Tabela18[[#This Row],[Estações]]="HMOFICINA","VMS",IFERROR(VLOOKUP(B13,'Cadastro Estacoes'!$A$2:$Z$201,26,0),"")) -> #ERROR! | G13: Feito | I13: Crachá | K13: LSP | L13: LSP | M13: 16/09/2019 | N13: C | O13: 01/03/2020 | P13: =IFERROR(VLOOKUP(B13,'Cadastro Estacoes'!$A:$B,2,0),"") -> SISMO®VALEPDM
A14: P0115 | B14: HMPDMDOLFIM15 | C14: Adaptar APR para manobra a ser realizada. | D14: 0 | E14: Permanente | F14: =IF(Tabela18[[#This Row],[Estações]]="HMOFICINA","VMS",IFERROR(VLOOKUP(B14,'Cadastro Estacoes'!$A$2:$Z$201,26,0),"")) -> #ERROR! | G14: Feito | I14: APR preenchida | K14: LSP | L14: LSP | M14: 16/09/2019 | N14: O | O14: 23/03/2020 | P14: =IFERROR(VLOOKUP(B14,'Cadastro Estacoes'!$A:$B,2,0),"") -> SISMO®VALEPDM
A15: P0116 | B15: HMPDMPIER01 | C15: Adaptar APR para manobra a ser realizada. | D15: 0 | E15: Permanente | F15: =IF(Tabela18[[#This Row],[Estações]]="HMOFICINA","VMS",IFERROR(VLOOKUP(B15,'Cadastro Estacoes'!$A$2:$Z$201,26,0),"")) -> #ERROR! | G15: Feito | I15: APR preenchida | K15: LSP | L15: LSP | M15: 16/09/2019 | N15: O | O15: 23/03/2020 | P15: =IFERROR(VLOOKUP(B15,'Cadastro Estacoes'!$A:$B,2,0),"") -> SISMO®VALEPDM
A16: P0117 | B16: HMPDMPIER03 | C16: Adaptar APR para manobra a ser realizada. | D16: 0 | E16: Permanente | F16: =IF(Tabela18[[#This Row],[Estações]]="HMOFICINA","VMS",IFERROR(VLOOKUP(B16,'Cadastro Estacoes'!$A$2:$Z$201,26,0),"")) -> #ERROR! | G16: Feito | I16: APR preenchida | K16: LSP | L16: LSP | M16: 16/09/2019 | N16: O | O16: 14/04/2020 | P16: =IFERROR(VLOOKUP(B16,'Cadastro Estacoes'!$A:$B,2,0),"") -> SISMO®VALEPDM
A17: P0118 | B17: HMPDMPIER01 | C17: Levar Cracha Vale | D17: 0 | E17: Permanente | F17: =IF(Tabela18[[#This Row],[Estações]]="HMOFICINA","VMS",IFERROR(VLOOKUP(B17,'Cadastro Estacoes'!$A$2:$Z$201,26,0),"")) -> #ERROR! | G17: Feito | I17: Crachá | K17: LSP | L17: LSP | M17: 16/09/2019 | N17: C | O17: 14/04/2020 | P17: =IFERROR(VLOOKUP(B17,'Cadastro Estacoes'!$A:$B,2,0),"") -> SISMO®VALEPDM
A18: P0119 | B18: HMPDMPIER03 | C18: Levar Cracha Vale | D18: 0 | E18: Permanente | F18: =IF(Tabela18[[#This Row],[Estações]]="HMOFICINA","VMS",IFERROR(VLOOKUP(B18,'Cadastro Estacoes'!$A$2:$Z$201,26,0),"")) -> #ERROR! | G18: Feito | I18: Crachá | K18: LSP | L18: LSP | M18: 16/09/2019 | N18: C | O18: 19/05/2020 | P18: =IFERROR(VLOOKUP(B18,'Cadastro Estacoes'!$A:$B,2,0),"") -> SISMO®VALEPDM
A19: P0120 | B19: HMCAPIER | C19: Levar nova régua para substituir a danificada | D19: 1 | E19: 20/10/2019 | F19: =IF(Tabela18[[#This Row],[Estações]]="HMOFICINA","VMS",IFERROR(VLOOKUP(B19,'Cadastro Estacoes'!$A$2:$Z$201,26,0),"")) -> #ERROR! | G19: Feito | H19: Lembrar da força da maré | I19: regua de maré | K19: FPM | L19: MAS | M19: 16/09/2019 | N19: C | O19: 19/05/2020 | P19: =IFERROR(VLOOKUP(B19,'Cadastro Estacoes'!$A:$B,2,0),"") -> SISMO®CATTALINI
A20: P0122 | B20: HMCAPIER | C20: Alterar catracas que estão fixando o equipamento na pilastra (pegador de uma quebrou) | D20: 0 | E20: 20/10/2019 | F20: =IF(Tabela18[[#This Row],[Estações]]="HMOFICINA","VMS",IFERROR(VLOOKUP(B20,'Cadastro Estacoes'!$A$2:$Z$201,26,0),"")) -> #ERROR! | G20: Feito | H20: substituir as DUAS | I20: DUAS catracas | K20: FPM | L20: MAS | M20: 16/09/2019 | N20: C | O20: 19/05/2020 | P20: =IFERROR(VLOOKUP(B20,'Cadastro Estacoes'!$A:$B,2,0),"") -> SISMO®CATTALINI
A21: P0123 | B21: HMPPMIRA | C21: p/ acessar caixa de equipamento levar chave do cadeado | D21: 0 | E21: 20/10/2019 | F21: =IF(Tabela18[[#This Row],[Estações]]="HMOFICINA","VMS",IFERROR(VLOOKUP(B21,'Cadastro Estacoes'!$A$2:$Z$201,26,0),"")) -> #ERROR! | G21: Feito | H21: caixa do equipamento foi movida para fora da 'casinha' e caixa da bateria está na casaria de fibra da patricagem | I21: chave que está no almo | K21: FPM | L21: MAS | M21: 16/09/2019 | N21: C | O21: 24/06/2020 | P21: =IFERROR(VLOOKUP(B21,'Cadastro Estacoes'!$A:$B,2,0),"") -> SISMO®PARANAGUAPILOTS
A22: P0146 | B22: HMLIB02 | C22: Lançar derivadores | D22: 1 | E22: 25/10/2019 | F22: =IF(Tabela18[[#This Row],[Estações]]="HMOFICINA","VMS",IFERROR(VLOOKUP(B22,'Cadastro Estacoes'!$A$2:$Z$201,26,0),"")) -> #ERROR! | G22: Feito | I22: derivador, gps reserva, ficha de derivadores | K22: EJC | L22: DMP | M22: 25/09/2019 | N22: C | O22: 13/07/2020 | P22: =IFERROR(VLOOKUP(B22,'Cadastro Estacoes'!$A:$B,2,0),"") -> SISMO®LIBRA/MULTI
A23: P0169 | B23: SEM ESTACAO | C23: Alinhar estrutura SSO | D23: 0 | E23: 01/10/2019 | F23: =IF(Tabela18[[#This Row],[Estações]]="HMOFICINA","VMS",IFERROR(VLOOKUP(B23,'Cadastro Estacoes'!$A$2:$Z$201,26,0),"")) -> #ERROR! | G23: Feito | H23: Reunião com Saraiva | K23: DSS | L23: ADC | M23: 26/09/2019 | N23: O | O23: 14/07/2020 | P23: =IFERROR(VLOOKUP(B23,'Cadastro Estacoes'!$A:$B,2,0),"") -> SEM PROJETO
A24: P0187 | B24: SEM ESTACAO | C24: Integrar sensor InnertialLabs | D24: 2 | E24: 05/10/2019 | F24: =IF(Tabela18[[#This Row],[Estações]]="HMOFICINA","VMS",IFERROR(VLOOKUP(B24,'Cadastro Estacoes'!$A$2:$Z$201,26,0),"")) -> #ERROR! | G24: Feito | H24: Aguardando o fabricante enviar o programa para Modificar dados binários | J24: 5 | K24: DSS | L24: LFF | M24: 30/09/2019 | N24: O | O24: 44279 | P24: =IFERROR(VLOOKUP(B24,'Cadastro Estacoes'!$A:$B,2,0),"") -> SEM PROJETO
A25: P0262 | B25: SEM ESTACAO | C25: Cadastrar toda equipe campo nos programas de milhagem | D25: 3 | E25: 11/10/2019 | F25: =IF(Tabela18[[#This Row],[Estações]]="HMOFICINA","VMS",IFERROR(VLOOKUP(B25,'Cadastro Estacoes'!$A$2:$Z$201,26,0),"")) -> #ERROR! | G25: Feito | J25: 1 | K25: DSS | L25: FMS | M25: 03/10/2019 | N25: O | O25: 14/07/2020 | P25: =IFERROR(VLOOKUP(B25,'Cadastro Estacoes'!$A:$B,2,0),"") -> SEM PROJETO
A26: P0327 | B26: HMPCMOLHE | C26: Pedir a abertura do cadeado da porta de acesso ao molhe | D26: 0 | E26: Permanente | F26: =IF(Tabela18[[#This Row],[Estações]]="HMOFICINA","VMS",IFERROR(VLOOKUP(B26,'Cadastro Estacoes'!$A$2:$Z$201,26,0),"")) -> #ERROR! | G26: Feito | H26: Falar com o Sérgio pra pegar a chave na Suzano Celulose com o operador de painel | K26: POF | L26: RO | M26: 14/10/2019 | N26: O | O26: 14/07/2020 | P26: =IFERROR(VLOOKUP(B26,'Cadastro Estacoes'!$A:$B,2,0),"") -> SISMO®PORTOCEL
A27: P0355 | B27: SEM ESTACAO | C27: Fazer procedimento de como fazer cabo GILL | D27: 2 | E27: 31/10/2019 | F27: =IF(Tabela18[[#This Row],[Estações]]="HMOFICINA","VMS",IFERROR(VLOOKUP(B27,'Cadastro Estacoes'!$A$2:$Z$201,26,0),"")) -> #ERROR! | G27: Feito | H27: Procedimento padrão (Verificar com Diego) | K27: DSS | L27: LFF | M27: 15/10/2019 | N27: O | O27: 29/07/2020 | P27: =IFERROR(VLOOKUP(B27,'Cadastro Estacoes'!$A:$B,2,0),"") -> SEM PROJETO
A28: P0368 | B28: HMBTCPBA | C28: Integrar Gill GMX no CR 300 | D28: 0 | E28: 31/03/2020 | F28: =IF(Tabela18[[#This Row],[Estações]]="HMOFICINA","VMS",IFERROR(VLOOKUP(B28,'Cadastro Estacoes'!$A$2:$Z$201,26,0),"")) -> #ERROR! | G28: Feito | H28: Aguardar chegada do sensor | I28: 1 anemomentro, 1 CR 300 | K28: CCL | L28: FMS | M28: 15/10/2019 | N28: O | O28: 07/08/2020 | P28: =IFERROR(VLOOKUP(B28,'Cadastro Estacoes'!$A:$B,2,0),"") -> SISMO®BTS
A29: P0416 | B29: HMSPTEBAR | C29: Arrancar prensacabo do eletroduto para passar cabo da estação | D29: 0 | E29: 31/01/2020 | F29: =IF(Tabela18[[#This Row],[Estações]]="HMOFICINA","VMS",IFERROR(VLOOKUP(B29,'Cadastro Estacoes'!$A$2:$Z$201,26,0),"")) -> #ERROR! | G29: Feito | H29: Prensacabo esta muito preso la, rosca ja esta se desfazendo | I29: Esmiril | K29: EMD | L29: LSP | M29: 28/10/2019 | N29: C | O29: 07/08/2020 | P29: =IFERROR(VLOOKUP(B29,'Cadastro Estacoes'!$A:$B,2,0),"") -> SISMO®SPPILOTS
A30: P0440 | B30: HMPSEPIER | C30: Lançar derivador na região de medição do SL | D30: 2 | E30: Permanente | F30: =IF(Tabela18[[#This Row],[Estações]]="HMOFICINA","VMS",IFERROR(VLOOKUP(B30,'Cadastro Estacoes'!$A$2:$Z$201,26,0),"")) -> #ERROR! | G30: Feito | H30: Vanessa mandou no grupo local ideal para lancamento | I30: derivador e gps | J30: 1 | K30: EMD | L30: VCP | M30: 02/11/2019 | N30: C | O30: 17/08/2020 | P30: =IFERROR(VLOOKUP(B30,'Cadastro Estacoes'!$A:$B,2,0),"") -> SISMO®PSE
A31: P0471 | B31: HMPCBOIA | C31: Levar cadeado CR50 quando for retirar o DCPS da água | D31: 1 | E31: Permanente | F31: =IF(Tabela18[[#This Row],[Estações]]="HMOFICINA","VMS",IFERROR(VLOOKUP(B31,'Cadastro Estacoes'!$A$2:$Z$201,26,0),"")) -> #ERROR! | G31: Feito | H31: Levar alicate corta cadeado | I31: Alicate corta cadeado | K31: POF | L31: RO | M31: 12/11/2019 | N31: C | O31: 17/08/2020 | P31: =IFERROR(VLOOKUP(B31,'Cadastro Estacoes'!$A:$B,2,0),"") -> SISMO®PORTOCEL
A32: P0510 | B32: SEM ESTACAO | C32: Revisar discos e partilhas da saveiro cabine simples | D32: 0 | E32: 25/11/2019 | F32: =IF(Tabela18[[#This Row],[Estações]]="HMOFICINA","VMS",IFERROR(VLOOKUP(B32,'Cadastro Estacoes'!$A$2:$Z$201,26,0),"")) -> #ERROR! | G32: Feito | H32: avaliar necessidade de trocar | J32: 1 | K32: DSS | L32: ESS | M32: 21/11/2019 | N32: O | O32: 21/08/2020 | P32: =IFERROR(VLOOKUP(B32,'Cadastro Estacoes'!$A:$B,2,0),"") -> SEM PROJETO
A33: P0513 | B33: SEM ESTACAO | C33: Avaliar sensores fabricados no Brasil - Nível (radar) -> Mafetech | D33: 0 | E33: 10/01/2020 | F33: =IF(Tabela18[[#This Row],[Estações]]="HMOFICINA","VMS",IFERROR(VLOOKUP(B33,'Cadastro Estacoes'!$A$2:$Z$201,26,0),"")) -> #ERROR! | G33: Feito | H33: Puxar o tema e passar para Desenvolvimento. Gustavo Henrique <vendas4@mafetech.com.br>; 19/12: enviado email solicitando infos | K33: DSS | L33: ADC | M33: 26/11/2019 | N33: O | O33: 21/08/2020 | P33: =IFERROR(VLOOKUP(B33,'Cadastro Estacoes'!$A:$B,2,0),"") -> SEM PROJETO
A34: P0524 | B34: HMTJUNITAPAJOS | C34: Substituir e fixar melhor cabo SL | D34: 0 | E34: 31/03/2020 | F34: =IF(Tabela18[[#This Row],[Estações]]="HMOFICINA","VMS",IFERROR(VLOOKUP(B34,'Cadastro Estacoes'!$A$2:$Z$201,26,0),"")) -> #ERROR! | G34: Feito | H34: Cabo com mau contato - necessário substituir e fixar melhor | I34: Cabo | K34: CCL | L34: DMP | M34: 29/11/2019 | N34: C | O34: 21/08/2020 | P34: =IFERROR(VLOOKUP(B34,'Cadastro Estacoes'!$A:$B,2,0),"") -> SISMO®TAPAJOS
A35: P0524 | B35: HMTJUNITAPAJOS | C35: Caixa de bateria com prensa-cabo para cima | D35: 0 | E35: 31/03/2020 | F35: =IF(Tabela18[[#This Row],[Estações]]="HMOFICINA","VMS",IFERROR(VLOOKUP(B35,'Cadastro Estacoes'!$A$2:$Z$201,26,0),"")) -> #ERROR! | G35: Feito | H35: Levar cabo de painel para poder virar a caixa | K35: CCL | L35: DMP | M35: 29/11/2019 | N35: C | O35: 44286 | P35: =IFERROR(VLOOKUP(B35,'Cadastro Estacoes'!$A:$B,2,0),"") -> SISMO®TAPAJOS
A36: P0542 | B36: HMSPTEBAR | C36: Verificar modem 548 | D36: 0 | E36: 29/02/2020 | F36: =IF(Tabela18[[#This Row],[Estações]]="HMOFICINA","VMS",IFERROR(VLOOKUP(B36,'Cadastro Estacoes'!$A$2:$Z$201,26,0),"")) -> #ERROR! | G36: Feito | H36: Modem caiu e não voltou mais | I36: Modem e chip | J36: 1 | K36: EMD | L36: ESS | M36: 04/12/2019 | N36: C | O36: 01/09/2020 | P36: =IFERROR(VLOOKUP(B36,'Cadastro Estacoes'!$A:$B,2,0),"") -> SISMO®SPPILOTS
A37: P0547 | B37: SEM ESTACAO | C37: Ativar pacote SonWave no XR 1500 E 5450 | D37: 0 | E37: 31/03/2020 | F37: =IF(Tabela18[[#This Row],[Estações]]="HMOFICINA","VMS",IFERROR(VLOOKUP(B37,'Cadastro Estacoes'!$A$2:$Z$201,26,0),"")) -> #ERROR! | G37: Feito | H37: Seguir instruções do e-mail após retorno do ADCP | K37: DSS | L37: FMS | M37: 04/12/2019 | N37: O | O37: 01/09/2020 | P37: =IFERROR(VLOOKUP(B37,'Cadastro Estacoes'!$A:$B,2,0),"") -> SEM PROJETO
A38: P0566 | B38: SEM ESTACAO | C38: Configurar Rastreadores | D38: 0 | E38: 31/12/2019 | F38: =IF(Tabela18[[#This Row],[Estações]]="HMOFICINA","VMS",IFERROR(VLOOKUP(B38,'Cadastro Estacoes'!$A$2:$Z$201,26,0),"")) -> #ERROR! | G38: Feito | K38: DSS | L38: LSP | M38: 09/12/2019 | N38: O | O38: 01/09/2020 | P38: =IFERROR(VLOOKUP(B38,'Cadastro Estacoes'!$A:$B,2,0),"") -> SEM PROJETO
A39: P0568 | B39: HMCAPIER | C39: Marcar novos RNs e pintá-los | D39: 0 | E39: 01/03/2020 | F39: =IF(Tabela18[[#This Row],[Estações]]="HMOFICINA","VMS",IFERROR(VLOOKUP(B39,'Cadastro Estacoes'!$A$2:$Z$201,26,0),"")) -> #ERROR! | G39: Feito | H39: dos antigos foram localizados somente dois - precisa marcar novos RNs | I39: marcas de RN + chumbador + pinta para pintura | J39: 2 | K39: FPM | L39: MAS | M39: 13/12/2019 | N39: C | O39: 11/09/2020 | P39: =IFERROR(VLOOKUP(B39,'Cadastro Estacoes'!$A:$B,2,0),"") -> SISMO®CATTALINI
A40: P0594 | B40: HMLIPIER | C40: Instalar Régua e Fazer Nivelamento | D40: 0 | E40: 20/02/2020 | F40: =IF(Tabela18[[#This Row],[Estações]]="HMOFICINA","VMS",IFERROR(VLOOKUP(B40,'Cadastro Estacoes'!$A$2:$Z$201,26,0),"")) -> #ERROR! | G40: Feito | H40: Atrelada a pendência P0673, deixar separado no almoxarifado e idenficado. | I40: Régua e demais materias para instalção da Régua; nível, mira | K40: EJC | L40: VCP | M40: 18/12/2019 | N40: C | O40: 24/09/2020 | P40: =IFERROR(VLOOKUP(B40,'Cadastro Estacoes'!$A:$B,2,0),"") -> SISMO®LIBRA/MULTI
A41: P0609 | B41: SEM ESTACAO | C41: Estudar controle de itens -> Instalados, Em campo, Em estoque | D41: 0 | E41: 02/01/2020 | F41: =IF(Tabela18[[#This Row],[Estações]]="HMOFICINA","VMS",IFERROR(VLOOKUP(B41,'Cadastro Estacoes'!$A$2:$Z$201,26,0),"")) -> #ERROR! | G41: Feito | H41: Discutir próxima reunião VCP/RMC | K41: DSS | L41: ADC | M41: 26/12/2019 | N41: O | O41: 06/10/2020 | P41: =IFERROR(VLOOKUP(B41,'Cadastro Estacoes'!$A:$B,2,0),"") -> SEM PROJETO
...

Sheet FichaCampoV2-POF
A1: Ficha de Campo (V2) | E1: Estação: | F1: HMPDMCTDPIER1 | I1: =VLOOKUP(F1,'Cadastro Estacoes'!A1:AB152,9,0) -> OPERACIONAL | J1: =VLOOKUP(F1,'Cadastro Estacoes'!A1:AB152,10,0) -> Oceanografia Pier | W1: {=IFERROR(INDEX(Pendencias!$A$2:$O$4333,SMALL(IF(Pendencias!$B$2:$B$4333=$F$1,ROW(Pendencias!$B$2:$B$4333)-1),ROW(A1)),1),"")} | X1: {=IFERROR(INDEX(Pendencias!$A$2:$O$4333,SMALL(IF(Pendencias!$B$2:$B$4333=$F$1,ROW(Pendencias!$B$2:$B$4333)-1),ROW(A1)),3),"")} | Y1: {=IFERROR(INDEX(Pendencias!$A$2:$O$4333,SMALL(IF(Pendencias!$B$2:$B$4333=$F$1,ROW(Pendencias!$B$2:$B$4333)-1),ROW(A1)),4),"")} | Z1: {=IFERROR(INDEX(Pendencias!$A$2:$O$4333,SMALL(IF(Pendencias!$B$2:$B$4333=$F$1,ROW(Pendencias!$B$2:$B$4333)-1),ROW(A1)),7),"")} | AA1: {=IF(IFERROR(INDEX(Pendencias!$A$2:$O$4333,SMALL(IF(Pendencias!$B$2:$B$4333=$F$1,ROW(Pendencias!$B$2:$B$4333)-1),ROW(A1)),9),"")=0,"",IFERROR(INDEX(Pendencias!$A$2:$O$4333,SMALL(IF(Pendencias!$B$2:$B$4333=$F$1,ROW(Pendencias!$B$2:$B$4333)-1),ROW(A1)),9),""))}
A2: Cód Viagem | D2: Equipe HM: | H2: Data: | W2: {=IFERROR(INDEX(Pendencias!$A$2:$O$4333,SMALL(IF(Pendencias!$B$2:$B$4333=$F$1,ROW(Pendencias!$B$2:$B$4333)-1),ROW(A2)),1),"")} | X2: {=IFERROR(INDEX(Pendencias!$A$2:$O$4333,SMALL(IF(Pendencias!$B$2:$B$4333=$F$1,ROW(Pendencias!$B$2:$B$4333)-1),ROW(A2)),3),"")} | Y2: {=IFERROR(INDEX(Pendencias!$A$2:$O$4333,SMALL(IF(Pendencias!$B$2:$B$4333=$F$1,ROW(Pendencias!$B$2:$B$4333)-1),ROW(A2)),4),"")} | Z2: {=IFERROR(INDEX(Pendencias!$A$2:$O$4333,SMALL(IF(Pendencias!$B$2:$B$4333=$F$1,ROW(Pendencias!$B$2:$B$4333)-1),ROW(A2)),7),"")} | AA2: {=IF(IFERROR(INDEX(Pendencias!$A$2:$O$4333,SMALL(IF(Pendencias!$B$2:$B$4333=$F$1,ROW(Pendencias!$B$2:$B$4333)-1),ROW(A2)),9),"")=0,"",IFERROR(INDEX(Pendencias!$A$2:$O$4333,SMALL(IF(Pendencias!$B$2:$B$4333=$F$1,ROW(Pendencias!$B$2:$B$4333)-1),ROW(A2)),9),""))}
W3: {=IFERROR(INDEX(Pendencias!$A$2:$O$4333,SMALL(IF(Pendencias!$B$2:$B$4333=$F$1,ROW(Pendencias!$B$2:$B$4333)-1),ROW(A3)),1),"")} | X3: {=IFERROR(INDEX(Pendencias!$A$2:$O$4333,SMALL(IF(Pendencias!$B$2:$B$4333=$F$1,ROW(Pendencias!$B$2:$B$4333)-1),ROW(A3)),3),"")} | Y3: {=IFERROR(INDEX(Pendencias!$A$2:$O$4333,SMALL(IF(Pendencias!$B$2:$B$4333=$F$1,ROW(Pendencias!$B$2:$B$4333)-1),ROW(A3)),4),"")} | Z3: {=IFERROR(INDEX(Pendencias!$A$2:$O$4333,SMALL(IF(Pendencias!$B$2:$B$4333=$F$1,ROW(Pendencias!$B$2:$B$4333)-1),ROW(A3)),7),"")} | AA3: {=IF(IFERROR(INDEX(Pendencias!$A$2:$O$4333,SMALL(IF(Pendencias!$B$2:$B$4333=$F$1,ROW(Pendencias!$B$2:$B$4333)-1),ROW(A3)),9),"")=0,"",IFERROR(INDEX(Pendencias!$A$2:$O$4333,SMALL(IF(Pendencias!$B$2:$B$4333=$F$1,ROW(Pendencias!$B$2:$B$4333)-1),ROW(A3)),9),""))}
A4: ID | B4: Pendências Previstas | J4: Prioridade | W4: {=IFERROR(INDEX(Pendencias!$A$2:$O$4333,SMALL(IF(Pendencias!$B$2:$B$4333=$F$1,ROW(Pendencias!$B$2:$B$4333)-1),ROW(A4)),1),"")} | X4: {=IFERROR(INDEX(Pendencias!$A$2:$O$4333,SMALL(IF(Pendencias!$B$2:$B$4333=$F$1,ROW(Pendencias!$B$2:$B$4333)-1),ROW(A4)),3),"")} | Y4: {=IFERROR(INDEX(Pendencias!$A$2:$O$4333,SMALL(IF(Pendencias!$B$2:$B$4333=$F$1,ROW(Pendencias!$B$2:$B$4333)-1),ROW(A4)),4),"")} | Z4: {=IFERROR(INDEX(Pendencias!$A$2:$O$4333,SMALL(IF(Pendencias!$B$2:$B$4333=$F$1,ROW(Pendencias!$B$2:$B$4333)-1),ROW(A4)),7),"")} | AA4: {=IF(IFERROR(INDEX(Pendencias!$A$2:$O$4333,SMALL(IF(Pendencias!$B$2:$B$4333=$F$1,ROW(Pendencias!$B$2:$B$4333)-1),ROW(A4)),9),"")=0,"",IFERROR(INDEX(Pendencias!$A$2:$O$4333,SMALL(IF(Pendencias!$B$2:$B$4333=$F$1,ROW(Pendencias!$B$2:$B$4333)-1),ROW(A4)),9),""))}
A5: {=IFERROR(INDEX($W$1:$Z$101,SMALL(IF($Z$1:$Z$101="A fazer",ROW($Z$1:$Z$101)),ROW(A1)),1),"")} | B5: {=IFERROR(INDEX($W$1:$Z$101,SMALL(IF($Z$1:$Z$101="A fazer",ROW($Z$1:$Z$101)),ROW(A1)),2),"")} | J5: {=IFERROR(INDEX($W$1:$Z$101,SMALL(IF($Z$1:$Z$101="A fazer",ROW($Z$1:$Z$101)),ROW(A1)),3),"")} | W5: {=IFERROR(INDEX(Pendencias!$A$2:$O$4333,SMALL(IF(Pendencias!$B$2:$B$4333=$F$1,ROW(Pendencias!$B$2:$B$4333)-1),ROW(A5)),1),"")} | X5: {=IFERROR(INDEX(Pendencias!$A$2:$O$4333,SMALL(IF(Pendencias!$B$2:$B$4333=$F$1,ROW(Pendencias!$B$2:$B$4333)-1),ROW(A5)),3),"")} | Y5: {=IFERROR(INDEX(Pendencias!$A$2:$O$4333,SMALL(IF(Pendencias!$B$2:$B$4333=$F$1,ROW(Pendencias!$B$2:$B$4333)-1),ROW(A5)),4),"")} | Z5: {=IFERROR(INDEX(Pendencias!$A$2:$O$4333,SMALL(IF(Pendencias!$B$2:$B$4333=$F$1,ROW(Pendencias!$B$2:$B$4333)-1),ROW(A5)),7),"")} | AA5: {=IF(IFERROR(INDEX(Pendencias!$A$2:$O$4333,SMALL(IF(Pendencias!$B$2:$B$4333=$F$1,ROW(Pendencias!$B$2:$B$4333)-1),ROW(A5)),9),"")=0,"",IFERROR(INDEX(Pendencias!$A$2:$O$4333,SMALL(IF(Pendencias!$B$2:$B$4333=$F$1,ROW(Pendencias!$B$2:$B$4333)-1),ROW(A5)),9),""))}
A6: {=IFERROR(INDEX($W$1:$Z$101,SMALL(IF($Z$1:$Z$101="A fazer",ROW($Z$1:$Z$101)),ROW(A2)),1),"")} | B6: {=IFERROR(INDEX($W$1:$Z$101,SMALL(IF($Z$1:$Z$101="A fazer",ROW($Z$1:$Z$101)),ROW(A2)),2),"")} | J6: {=IFERROR(INDEX($W$1:$Z$101,SMALL(IF($Z$1:$Z$101="A fazer",ROW($Z$1:$Z$101)),ROW(A2)),3),"")} | W6: {=IFERROR(INDEX(Pendencias!$A$2:$O$4333,SMALL(IF(Pendencias!$B$2:$B$4333=$F$1,ROW(Pendencias!$B$2:$B$4333)-1),ROW(A6)),1),"")} | X6: {=IFERROR(INDEX(Pendencias!$A$2:$O$4333,SMALL(IF(Pendencias!$B$2:$B$4333=$F$1,ROW(Pendencias!$B$2:$B$4333)-1),ROW(A6)),3),"")} | Y6: {=IFERROR(INDEX(Pendencias!$A$2:$O$4333,SMALL(IF(Pendencias!$B$2:$B$4333=$F$1,ROW(Pendencias!$B$2:$B$4333)-1),ROW(A6)),4),"")} | Z6: {=IFERROR(INDEX(Pendencias!$A$2:$O$4333,SMALL(IF(Pendencias!$B$2:$B$4333=$F$1,ROW(Pendencias!$B$2:$B$4333)-1),ROW(A6)),7),"")} | AA6: {=IF(IFERROR(INDEX(Pendencias!$A$2:$O$4333,SMALL(IF(Pendencias!$B$2:$B$4333=$F$1,ROW(Pendencias!$B$2:$B$4333)-1),ROW(A6)),9),"")=0,"",IFERROR(INDEX(Pendencias!$A$2:$O$4333,SMALL(IF(Pendencias!$B$2:$B$4333=$F$1,ROW(Pendencias!$B$2:$B$4333)-1),ROW(A6)),9),""))}
A7: {=IFERROR(INDEX($W$1:$Z$101,SMALL(IF($Z$1:$Z$101="A fazer",ROW($Z$1:$Z$101)),ROW(A3)),1),"")} | B7: {=IFERROR(INDEX($W$1:$Z$101,SMALL(IF($Z$1:$Z$101="A fazer",ROW($Z$1:$Z$101)),ROW(A3)),2),"")} | J7: {=IFERROR(INDEX($W$1:$Z$101,SMALL(IF($Z$1:$Z$101="A fazer",ROW($Z$1:$Z$101)),ROW(A3)),3),"")} | W7: {=IFERROR(INDEX(Pendencias!$A$2:$O$4333,SMALL(IF(Pendencias!$B$2:$B$4333=$F$1,ROW(Pendencias!$B$2:$B$4333)-1),ROW(A7)),1),"")} | X7: {=IFERROR(INDEX(Pendencias!$A$2:$O$4333,SMALL(IF(Pendencias!$B$2:$B$4333=$F$1,ROW(Pendencias!$B$2:$B$4333)-1),ROW(A7)),3),"")} | Y7: {=IFERROR(INDEX(Pendencias!$A$2:$O$4333,SMALL(IF(Pendencias!$B$2:$B$4333=$F$1,ROW(Pendencias!$B$2:$B$4333)-1),ROW(A7)),4),"")} | Z7: {=IFERROR(INDEX(Pendencias!$A$2:$O$4333,SMALL(IF(Pendencias!$B$2:$B$4333=$F$1,ROW(Pendencias!$B$2:$B$4333)-1),ROW(A7)),7),"")} | AA7: {=IF(IFERROR(INDEX(Pendencias!$A$2:$O$4333,SMALL(IF(Pendencias!$B$2:$B$4333=$F$1,ROW(Pendencias!$B$2:$B$4333)-1),ROW(A7)),9),"")=0,"",IFERROR(INDEX(Pendencias!$A$2:$O$4333,SMALL(IF(Pendencias!$B$2:$B$4333=$F$1,ROW(Pendencias!$B$2:$B$4333)-1),ROW(A7)),9),""))}
A8: {=IFERROR(INDEX($W$1:$Z$101,SMALL(IF($Z$1:$Z$101="A fazer",ROW($Z$1:$Z$101)),ROW(A4)),1),"")} | B8: {=IFERROR(INDEX($W$1:$Z$101,SMALL(IF($Z$1:$Z$101="A fazer",ROW($Z$1:$Z$101)),ROW(A4)),2),"")} | J8: {=IFERROR(INDEX($W$1:$Z$101,SMALL(IF($Z$1:$Z$101="A fazer",ROW($Z$1:$Z$101)),ROW(A4)),3),"")} | W8: {=IFERROR(INDEX(Pendencias!$A$2:$O$4333,SMALL(IF(Pendencias!$B$2:$B$4333=$F$1,ROW(Pendencias!$B$2:$B$4333)-1),ROW(A8)),1),"")} | X8: {=IFERROR(INDEX(Pendencias!$A$2:$O$4333,SMALL(IF(Pendencias!$B$2:$B$4333=$F$1,ROW(Pendencias!$B$2:$B$4333)-1),ROW(A8)),3),"")} | Y8: {=IFERROR(INDEX(Pendencias!$A$2:$O$4333,SMALL(IF(Pendencias!$B$2:$B$4333=$F$1,ROW(Pendencias!$B$2:$B$4333)-1),ROW(A8)),4),"")} | Z8: {=IFERROR(INDEX(Pendencias!$A$2:$O$4333,SMALL(IF(Pendencias!$B$2:$B$4333=$F$1,ROW(Pendencias!$B$2:$B$4333)-1),ROW(A8)),7),"")} | AA8: {=IF(IFERROR(INDEX(Pendencias!$A$2:$O$4333,SMALL(IF(Pendencias!$B$2:$B$4333=$F$1,ROW(Pendencias!$B$2:$B$4333)-1),ROW(A8)),9),"")=0,"",IFERROR(INDEX(Pendencias!$A$2:$O$4333,SMALL(IF(Pendencias!$B$2:$B$4333=$F$1,ROW(Pendencias!$B$2:$B$4333)-1),ROW(A8)),9),""))}
A9: {=IFERROR(INDEX($W$1:$Z$101,SMALL(IF($Z$1:$Z$101="A fazer",ROW($Z$1:$Z$101)),ROW(A5)),1),"")} | B9: {=IFERROR(INDEX($W$1:$Z$101,SMALL(IF($Z$1:$Z$101="A fazer",ROW($Z$1:$Z$101)),ROW(A5)),2),"")} | J9: {=IFERROR(INDEX($W$1:$Z$101,SMALL(IF($Z$1:$Z$101="A fazer",ROW($Z$1:$Z$101)),ROW(A5)),3),"")} | W9: {=IFERROR(INDEX(Pendencias!$A$2:$O$4333,SMALL(IF(Pendencias!$B$2:$B$4333=$F$1,ROW(Pendencias!$B$2:$B$4333)-1),ROW(A9)),1),"")} | X9: {=IFERROR(INDEX(Pendencias!$A$2:$O$4333,SMALL(IF(Pendencias!$B$2:$B$4333=$F$1,ROW(Pendencias!$B$2:$B$4333)-1),ROW(A9)),3),"")} | Y9: {=IFERROR(INDEX(Pendencias!$A$2:$O$4333,SMALL(IF(Pendencias!$B$2:$B$4333=$F$1,ROW(Pendencias!$B$2:$B$4333)-1),ROW(A9)),4),"")} | Z9: {=IFERROR(INDEX(Pendencias!$A$2:$O$4333,SMALL(IF(Pendencias!$B$2:$B$4333=$F$1,ROW(Pendencias!$B$2:$B$4333)-1),ROW(A9)),7),"")} | AA9: {=IF(IFERROR(INDEX(Pendencias!$A$2:$O$4333,SMALL(IF(Pendencias!$B$2:$B$4333=$F$1,ROW(Pendencias!$B$2:$B$4333)-1),ROW(A9)),9),"")=0,"",IFERROR(INDEX(Pendencias!$A$2:$O$4333,SMALL(IF(Pendencias!$B$2:$B$4333=$F$1,ROW(Pendencias!$B$2:$B$4333)-1),ROW(A9)),9),""))}
A10: {=IFERROR(INDEX($W$1:$Z$101,SMALL(IF($Z$1:$Z$101="A fazer",ROW($Z$1:$Z$101)),ROW(A6)),1),"")} | B10: {=IFERROR(INDEX($W$1:$Z$101,SMALL(IF($Z$1:$Z$101="A fazer",ROW($Z$1:$Z$101)),ROW(A6)),2),"")} | J10: {=IFERROR(INDEX($W$1:$Z$101,SMALL(IF($Z$1:$Z$101="A fazer",ROW($Z$1:$Z$101)),ROW(A6)),3),"")} | W10: {=IFERROR(INDEX(Pendencias!$A$2:$O$4333,SMALL(IF(Pendencias!$B$2:$B$4333=$F$1,ROW(Pendencias!$B$2:$B$4333)-1),ROW(A10)),1),"")} | X10: {=IFERROR(INDEX(Pendencias!$A$2:$O$4333,SMALL(IF(Pendencias!$B$2:$B$4333=$F$1,ROW(Pendencias!$B$2:$B$4333)-1),ROW(A10)),3),"")} | Y10: {=IFERROR(INDEX(Pendencias!$A$2:$O$4333,SMALL(IF(Pendencias!$B$2:$B$4333=$F$1,ROW(Pendencias!$B$2:$B$4333)-1),ROW(A10)),4),"")} | Z10: {=IFERROR(INDEX(Pendencias!$A$2:$O$4333,SMALL(IF(Pendencias!$B$2:$B$4333=$F$1,ROW(Pendencias!$B$2:$B$4333)-1),ROW(A10)),7),"")} | AA10: {=IF(IFERROR(INDEX(Pendencias!$A$2:$O$4333,SMALL(IF(Pendencias!$B$2:$B$4333=$F$1,ROW(Pendencias!$B$2:$B$4333)-1),ROW(A10)),9),"")=0,"",IFERROR(INDEX(Pendencias!$A$2:$O$4333,SMALL(IF(Pendencias!$B$2:$B$4333=$F$1,ROW(Pendencias!$B$2:$B$4333)-1),ROW(A10)),9),""))}
A11: {=IFERROR(INDEX($W$1:$Z$101,SMALL(IF($Z$1:$Z$101="A fazer",ROW($Z$1:$Z$101)),ROW(A7)),1),"")} | B11: {=IFERROR(INDEX($W$1:$Z$101,SMALL(IF($Z$1:$Z$101="A fazer",ROW($Z$1:$Z$101)),ROW(A7)),2),"")} | J11: {=IFERROR(INDEX($W$1:$Z$101,SMALL(IF($Z$1:$Z$101="A fazer",ROW($Z$1:$Z$101)),ROW(A7)),3),"")} | W11: {=IFERROR(INDEX(Pendencias!$A$2:$O$4333,SMALL(IF(Pendencias!$B$2:$B$4333=$F$1,ROW(Pendencias!$B$2:$B$4333)-1),ROW(A11)),1),"")} | X11: {=IFERROR(INDEX(Pendencias!$A$2:$O$4333,SMALL(IF(Pendencias!$B$2:$B$4333=$F$1,ROW(Pendencias!$B$2:$B$4333)-1),ROW(A11)),3),"")} | Y11: {=IFERROR(INDEX(Pendencias!$A$2:$O$4333,SMALL(IF(Pendencias!$B$2:$B$4333=$F$1,ROW(Pendencias!$B$2:$B$4333)-1),ROW(A11)),4),"")} | Z11: {=IFERROR(INDEX(Pendencias!$A$2:$O$4333,SMALL(IF(Pendencias!$B$2:$B$4333=$F$1,ROW(Pendencias!$B$2:$B$4333)-1),ROW(A11)),7),"")} | AA11: {=IF(IFERROR(INDEX(Pendencias!$A$2:$O$4333,SMALL(IF(Pendencias!$B$2:$B$4333=$F$1,ROW(Pendencias!$B$2:$B$4333)-1),ROW(A11)),9),"")=0,"",IFERROR(INDEX(Pendencias!$A$2:$O$4333,SMALL(IF(Pendencias!$B$2:$B$4333=$F$1,ROW(Pendencias!$B$2:$B$4333)-1),ROW(A11)),9),""))}
A12: {=IFERROR(INDEX($W$1:$Z$101,SMALL(IF($Z$1:$Z$101="A fazer",ROW($Z$1:$Z$101)),ROW(A8)),1),"")} | B12: {=IFERROR(INDEX($W$1:$Z$101,SMALL(IF($Z$1:$Z$101="A fazer",ROW($Z$1:$Z$101)),ROW(A8)),2),"")} | J12: {=IFERROR(INDEX($W$1:$Z$101,SMALL(IF($Z$1:$Z$101="A fazer",ROW($Z$1:$Z$101)),ROW(A8)),3),"")} | W12: {=IFERROR(INDEX(Pendencias!$A$2:$O$4333,SMALL(IF(Pendencias!$B$2:$B$4333=$F$1,ROW(Pendencias!$B$2:$B$4333)-1),ROW(A12)),1),"")} | X12: {=IFERROR(INDEX(Pendencias!$A$2:$O$4333,SMALL(IF(Pendencias!$B$2:$B$4333=$F$1,ROW(Pendencias!$B$2:$B$4333)-1),ROW(A12)),3),"")} | Y12: {=IFERROR(INDEX(Pendencias!$A$2:$O$4333,SMALL(IF(Pendencias!$B$2:$B$4333=$F$1,ROW(Pendencias!$B$2:$B$4333)-1),ROW(A12)),4),"")} | Z12: {=IFERROR(INDEX(Pendencias!$A$2:$O$4333,SMALL(IF(Pendencias!$B$2:$B$4333=$F$1,ROW(Pendencias!$B$2:$B$4333)-1),ROW(A12)),7),"")} | AA12: {=IF(IFERROR(INDEX(Pendencias!$A$2:$O$4333,SMALL(IF(Pendencias!$B$2:$B$4333=$F$1,ROW(Pendencias!$B$2:$B$4333)-1),ROW(A12)),9),"")=0,"",IFERROR(INDEX(Pendencias!$A$2:$O$4333,SMALL(IF(Pendencias!$B$2:$B$4333=$F$1,ROW(Pendencias!$B$2:$B$4333)-1),ROW(A12)),9),""))}
A13: {=IFERROR(INDEX($W$1:$Z$101,SMALL(IF($Z$1:$Z$101="A fazer",ROW($Z$1:$Z$101)),ROW(A9)),1),"")} | B13: {=IFERROR(INDEX($W$1:$Z$101,SMALL(IF($Z$1:$Z$101="A fazer",ROW($Z$1:$Z$101)),ROW(A9)),2),"")} | J13: {=IFERROR(INDEX($W$1:$Z$101,SMALL(IF($Z$1:$Z$101="A fazer",ROW($Z$1:$Z$101)),ROW(A9)),3),"")} | W13: {=IFERROR(INDEX(Pendencias!$A$2:$O$4333,SMALL(IF(Pendencias!$B$2:$B$4333=$F$1,ROW(Pendencias!$B$2:$B$4333)-1),ROW(A13)),1),"")} | X13: {=IFERROR(INDEX(Pendencias!$A$2:$O$4333,SMALL(IF(Pendencias!$B$2:$B$4333=$F$1,ROW(Pendencias!$B$2:$B$4333)-1),ROW(A13)),3),"")} | Y13: {=IFERROR(INDEX(Pendencias!$A$2:$O$4333,SMALL(IF(Pendencias!$B$2:$B$4333=$F$1,ROW(Pendencias!$B$2:$B$4333)-1),ROW(A13)),4),"")} | Z13: {=IFERROR(INDEX(Pendencias!$A$2:$O$4333,SMALL(IF(Pendencias!$B$2:$B$4333=$F$1,ROW(Pendencias!$B$2:$B$4333)-1),ROW(A13)),7),"")} | AA13: {=IF(IFERROR(INDEX(Pendencias!$A$2:$O$4333,SMALL(IF(Pendencias!$B$2:$B$4333=$F$1,ROW(Pendencias!$B$2:$B$4333)-1),ROW(A13)),9),"")=0,"",IFERROR(INDEX(Pendencias!$A$2:$O$4333,SMALL(IF(Pendencias!$B$2:$B$4333=$F$1,ROW(Pendencias!$B$2:$B$4333)-1),ROW(A13)),9),""))}
A14: {=IFERROR(INDEX($W$1:$Z$101,SMALL(IF($Z$1:$Z$101="A fazer",ROW($Z$1:$Z$101)),ROW(A10)),1),"")} | B14: {=IFERROR(INDEX($W$1:$Z$101,SMALL(IF($Z$1:$Z$101="A fazer",ROW($Z$1:$Z$101)),ROW(A10)),2),"")} | J14: {=IFERROR(INDEX($W$1:$Z$101,SMALL(IF($Z$1:$Z$101="A fazer",ROW($Z$1:$Z$101)),ROW(A10)),3),"")} | W14: {=IFERROR(INDEX(Pendencias!$A$2:$O$4333,SMALL(IF(Pendencias!$B$2:$B$4333=$F$1,ROW(Pendencias!$B$2:$B$4333)-1),ROW(A14)),1),"")} | X14: {=IFERROR(INDEX(Pendencias!$A$2:$O$4333,SMALL(IF(Pendencias!$B$2:$B$4333=$F$1,ROW(Pendencias!$B$2:$B$4333)-1),ROW(A14)),3),"")} | Y14: {=IFERROR(INDEX(Pendencias!$A$2:$O$4333,SMALL(IF(Pendencias!$B$2:$B$4333=$F$1,ROW(Pendencias!$B$2:$B$4333)-1),ROW(A14)),4),"")} | Z14: {=IFERROR(INDEX(Pendencias!$A$2:$O$4333,SMALL(IF(Pendencias!$B$2:$B$4333=$F$1,ROW(Pendencias!$B$2:$B$4333)-1),ROW(A14)),7),"")} | AA14: {=IF(IFERROR(INDEX(Pendencias!$A$2:$O$4333,SMALL(IF(Pendencias!$B$2:$B$4333=$F$1,ROW(Pendencias!$B$2:$B$4333)-1),ROW(A14)),9),"")=0,"",IFERROR(INDEX(Pendencias!$A$2:$O$4333,SMALL(IF(Pendencias!$B$2:$B$4333=$F$1,ROW(Pendencias!$B$2:$B$4333)-1),ROW(A14)),9),""))}
A15: {=IFERROR(INDEX($W$1:$Z$101,SMALL(IF($Z$1:$Z$101="A fazer",ROW($Z$1:$Z$101)),ROW(A11)),1),"")} | B15: {=IFERROR(INDEX($W$1:$Z$101,SMALL(IF($Z$1:$Z$101="A fazer",ROW($Z$1:$Z$101)),ROW(A11)),2),"")} | J15: {=IFERROR(INDEX($W$1:$Z$101,SMALL(IF($Z$1:$Z$101="A fazer",ROW($Z$1:$Z$101)),ROW(A11)),3),"")} | W15: {=IFERROR(INDEX(Pendencias!$A$2:$O$4333,SMALL(IF(Pendencias!$B$2:$B$4333=$F$1,ROW(Pendencias!$B$2:$B$4333)-1),ROW(A15)),1),"")} | X15: {=IFERROR(INDEX(Pendencias!$A$2:$O$4333,SMALL(IF(Pendencias!$B$2:$B$4333=$F$1,ROW(Pendencias!$B$2:$B$4333)-1),ROW(A15)),3),"")} | Y15: {=IFERROR(INDEX(Pendencias!$A$2:$O$4333,SMALL(IF(Pendencias!$B$2:$B$4333=$F$1,ROW(Pendencias!$B$2:$B$4333)-1),ROW(A15)),4),"")} | Z15: {=IFERROR(INDEX(Pendencias!$A$2:$O$4333,SMALL(IF(Pendencias!$B$2:$B$4333=$F$1,ROW(Pendencias!$B$2:$B$4333)-1),ROW(A15)),7),"")} | AA15: {=IF(IFERROR(INDEX(Pendencias!$A$2:$O$4333,SMALL(IF(Pendencias!$B$2:$B$4333=$F$1,ROW(Pendencias!$B$2:$B$4333)-1),ROW(A15)),9),"")=0,"",IFERROR(INDEX(Pendencias!$A$2:$O$4333,SMALL(IF(Pendencias!$B$2:$B$4333=$F$1,ROW(Pendencias!$B$2:$B$4333)-1),ROW(A15)),9),""))}
W16: {=IFERROR(INDEX(Pendencias!$A$2:$O$4333,SMALL(IF(Pendencias!$B$2:$B$4333=$F$1,ROW(Pendencias!$B$2:$B$4333)-1),ROW(A16)),1),"")} | X16: {=IFERROR(INDEX(Pendencias!$A$2:$O$4333,SMALL(IF(Pendencias!$B$2:$B$4333=$F$1,ROW(Pendencias!$B$2:$B$4333)-1),ROW(A16)),3),"")} | Y16: {=IFERROR(INDEX(Pendencias!$A$2:$O$4333,SMALL(IF(Pendencias!$B$2:$B$4333=$F$1,ROW(Pendencias!$B$2:$B$4333)-1),ROW(A16)),4),"")} | Z16: {=IFERROR(INDEX(Pendencias!$A$2:$O$4333,SMALL(IF(Pendencias!$B$2:$B$4333=$F$1,ROW(Pendencias!$B$2:$B$4333)-1),ROW(A16)),7),"")} | AA16: {=IF(IFERROR(INDEX(Pendencias!$A$2:$O$4333,SMALL(IF(Pendencias!$B$2:$B$4333=$F$1,ROW(Pendencias!$B$2:$B$4333)-1),ROW(A16)),9),"")=0,"",IFERROR(INDEX(Pendencias!$A$2:$O$4333,SMALL(IF(Pendencias!$B$2:$B$4333=$F$1,ROW(Pendencias!$B$2:$B$4333)-1),ROW(A16)),9),""))}
A17: Problemas em aberto na Estação | W17: {=IFERROR(INDEX(Pendencias!$A$2:$O$4333,SMALL(IF(Pendencias!$B$2:$B$4333=$F$1,ROW(Pendencias!$B$2:$B$4333)-1),ROW(A17)),1),"")} | X17: {=IFERROR(INDEX(Pendencias!$A$2:$O$4333,SMALL(IF(Pendencias!$B$2:$B$4333=$F$1,ROW(Pendencias!$B$2:$B$4333)-1),ROW(A17)),3),"")} | Y17: {=IFERROR(INDEX(Pendencias!$A$2:$O$4333,SMALL(IF(Pendencias!$B$2:$B$4333=$F$1,ROW(Pendencias!$B$2:$B$4333)-1),ROW(A17)),4),"")} | Z17: {=IFERROR(INDEX(Pendencias!$A$2:$O$4333,SMALL(IF(Pendencias!$B$2:$B$4333=$F$1,ROW(Pendencias!$B$2:$B$4333)-1),ROW(A17)),7),"")} | AA17: {=IF(IFERROR(INDEX(Pendencias!$A$2:$O$4333,SMALL(IF(Pendencias!$B$2:$B$4333=$F$1,ROW(Pendencias!$B$2:$B$4333)-1),ROW(A17)),9),"")=0,"",IFERROR(INDEX(Pendencias!$A$2:$O$4333,SMALL(IF(Pendencias!$B$2:$B$4333=$F$1,ROW(Pendencias!$B$2:$B$4333)-1),ROW(A17)),9),""))}
A18: KEY | B18: DATA INÍCIO | C18: PRIORIDADE | D18: PROBLEMA | G18: RESUMO DO PROBLEMA | W18: {=IFERROR(INDEX(Pendencias!$A$2:$O$4333,SMALL(IF(Pendencias!$B$2:$B$4333=$F$1,ROW(Pendencias!$B$2:$B$4333)-1),ROW(A18)),1),"")} | X18: {=IFERROR(INDEX(Pendencias!$A$2:$O$4333,SMALL(IF(Pendencias!$B$2:$B$4333=$F$1,ROW(Pendencias!$B$2:$B$4333)-1),ROW(A18)),3),"")} | Y18: {=IFERROR(INDEX(Pendencias!$A$2:$O$4333,SMALL(IF(Pendencias!$B$2:$B$4333=$F$1,ROW(Pendencias!$B$2:$B$4333)-1),ROW(A18)),4),"")} | Z18: {=IFERROR(INDEX(Pendencias!$A$2:$O$4333,SMALL(IF(Pendencias!$B$2:$B$4333=$F$1,ROW(Pendencias!$B$2:$B$4333)-1),ROW(A18)),7),"")} | AA18: {=IF(IFERROR(INDEX(Pendencias!$A$2:$O$4333,SMALL(IF(Pendencias!$B$2:$B$4333=$F$1,ROW(Pendencias!$B$2:$B$4333)-1),ROW(A18)),9),"")=0,"",IFERROR(INDEX(Pendencias!$A$2:$O$4333,SMALL(IF(Pendencias!$B$2:$B$4333=$F$1,ROW(Pendencias!$B$2:$B$4333)-1),ROW(A18)),9),""))}
A19: =IFERROR(INDEX('Problemas em aberto'!$A$2:$G$303,SMALL(IF('Problemas em aberto'!$E$2:$E$303=IFERROR(VLOOKUP($F$1,Tabela5[#All],12,0),""),ROW('Problemas em aberto'!$E$2:$E$303)-1),ROW(A1)),1),"") -> #ERROR! | B19: =IFERROR(INDEX('Problemas em aberto'!$A$2:$G$303,SMALL(IF('Problemas em aberto'!$E$2:$E$303=IFERROR(VLOOKUP($F$1,Tabela5[#All],12,0),""),ROW('Problemas em aberto'!$E$2:$E$303)-1),ROW(A1)),2),"") -> #ERROR! | C19: =IFERROR(INDEX('Problemas em aberto'!$A$2:$G$303,SMALL(IF('Problemas em aberto'!$E$2:$E$303=IFERROR(VLOOKUP($F$1,Tabela5[#All],12,0),""),ROW('Problemas em aberto'!$E$2:$E$303)-1),ROW(A1)),7),"") -> #ERROR! | D19: =IFERROR(INDEX('Problemas em aberto'!$A$2:$G$303,SMALL(IF('Problemas em aberto'!$E$2:$E$303=IFERROR(VLOOKUP($F$1,Tabela5[#All],12,0),""),ROW('Problemas em aberto'!$E$2:$E$303)-1),ROW(A1)),6),"") -> #ERROR! | G19: =IFERROR(INDEX('Problemas em aberto'!$A$2:$G$303,SMALL(IF('Problemas em aberto'!$E$2:$E$303=IFERROR(VLOOKUP($F$1,Tabela5[#All],12,0),""),ROW('Problemas em aberto'!$E$2:$E$303)-1),ROW(A1)),4),"") -> #ERROR! | W19: {=IFERROR(INDEX(Pendencias!$A$2:$O$4333,SMALL(IF(Pendencias!$B$2:$B$4333=$F$1,ROW(Pendencias!$B$2:$B$4333)-1),ROW(A19)),1),"")} | X19: {=IFERROR(INDEX(Pendencias!$A$2:$O$4333,SMALL(IF(Pendencias!$B$2:$B$4333=$F$1,ROW(Pendencias!$B$2:$B$4333)-1),ROW(A19)),3),"")} | Y19: {=IFERROR(INDEX(Pendencias!$A$2:$O$4333,SMALL(IF(Pendencias!$B$2:$B$4333=$F$1,ROW(Pendencias!$B$2:$B$4333)-1),ROW(A19)),4),"")} | Z19: {=IFERROR(INDEX(Pendencias!$A$2:$O$4333,SMALL(IF(Pendencias!$B$2:$B$4333=$F$1,ROW(Pendencias!$B$2:$B$4333)-1),ROW(A19)),7),"")} | AA19: {=IF(IFERROR(INDEX(Pendencias!$A$2:$O$4333,SMALL(IF(Pendencias!$B$2:$B$4333=$F$1,ROW(Pendencias!$B$2:$B$4333)-1),ROW(A19)),9),"")=0,"",IFERROR(INDEX(Pendencias!$A$2:$O$4333,SMALL(IF(Pendencias!$B$2:$B$4333=$F$1,ROW(Pendencias!$B$2:$B$4333)-1),ROW(A19)),9),""))}
A20: =IFERROR(INDEX('Problemas em aberto'!$A$2:$G$303,SMALL(IF('Problemas em aberto'!$E$2:$E$303=IFERROR(VLOOKUP($F$1,Tabela5[#All],12,0),""),ROW('Problemas em aberto'!$E$2:$E$303)-1),ROW(A2)),1),"") -> #ERROR! | B20: =IFERROR(INDEX('Problemas em aberto'!$A$2:$G$303,SMALL(IF('Problemas em aberto'!$E$2:$E$303=IFERROR(VLOOKUP($F$1,Tabela5[#All],12,0),""),ROW('Problemas em aberto'!$E$2:$E$303)-1),ROW(A2)),2),"") -> #ERROR! | C20: =IFERROR(INDEX('Problemas em aberto'!$A$2:$G$303,SMALL(IF('Problemas em aberto'!$E$2:$E$303=IFERROR(VLOOKUP($F$1,Tabela5[#All],12,0),""),ROW('Problemas em aberto'!$E$2:$E$303)-1),ROW(A2)),7),"") -> #ERROR! | D20: =IFERROR(INDEX('Problemas em aberto'!$A$2:$G$303,SMALL(IF('Problemas em aberto'!$E$2:$E$303=IFERROR(VLOOKUP($F$1,Tabela5[#All],12,0),""),ROW('Problemas em aberto'!$E$2:$E$303)-1),ROW(A2)),6),"") -> #ERROR! | G20: =IFERROR(INDEX('Problemas em aberto'!$A$2:$G$303,SMALL(IF('Problemas em aberto'!$E$2:$E$303=IFERROR(VLOOKUP($F$1,Tabela5[#All],12,0),""),ROW('Problemas em aberto'!$E$2:$E$303)-1),ROW(A2)),4),"") -> #ERROR! | W20: {=IFERROR(INDEX(Pendencias!$A$2:$O$4333,SMALL(IF(Pendencias!$B$2:$B$4333=$F$1,ROW(Pendencias!$B$2:$B$4333)-1),ROW(A20)),1),"")} | X20: {=IFERROR(INDEX(Pendencias!$A$2:$O$4333,SMALL(IF(Pendencias!$B$2:$B$4333=$F$1,ROW(Pendencias!$B$2:$B$4333)-1),ROW(A20)),3),"")} | Y20: {=IFERROR(INDEX(Pendencias!$A$2:$O$4333,SMALL(IF(Pendencias!$B$2:$B$4333=$F$1,ROW(Pendencias!$B$2:$B$4333)-1),ROW(A20)),4),"")} | Z20: {=IFERROR(INDEX(Pendencias!$A$2:$O$4333,SMALL(IF(Pendencias!$B$2:$B$4333=$F$1,ROW(Pendencias!$B$2:$B$4333)-1),ROW(A20)),7),"")} | AA20: {=IF(IFERROR(INDEX(Pendencias!$A$2:$O$4333,SMALL(IF(Pendencias!$B$2:$B$4333=$F$1,ROW(Pendencias!$B$2:$B$4333)-1),ROW(A20)),9),"")=0,"",IFERROR(INDEX(Pendencias!$A$2:$O$4333,SMALL(IF(Pendencias!$B$2:$B$4333=$F$1,ROW(Pendencias!$B$2:$B$4333)-1),ROW(A20)),9),""))}
A21: =IFERROR(INDEX('Problemas em aberto'!$A$2:$G$303,SMALL(IF('Problemas em aberto'!$E$2:$E$303=IFERROR(VLOOKUP($F$1,Tabela5[#All],12,0),""),ROW('Problemas em aberto'!$E$2:$E$303)-1),ROW(A3)),1),"") -> #ERROR! | B21: =IFERROR(INDEX('Problemas em aberto'!$A$2:$G$303,SMALL(IF('Problemas em aberto'!$E$2:$E$303=IFERROR(VLOOKUP($F$1,Tabela5[#All],12,0),""),ROW('Problemas em aberto'!$E$2:$E$303)-1),ROW(A3)),2),"") -> #ERROR! | C21: =IFERROR(INDEX('Problemas em aberto'!$A$2:$G$303,SMALL(IF('Problemas em aberto'!$E$2:$E$303=IFERROR(VLOOKUP($F$1,Tabela5[#All],12,0),""),ROW('Problemas em aberto'!$E$2:$E$303)-1),ROW(A3)),7),"") -> #ERROR! | D21: =IFERROR(INDEX('Problemas em aberto'!$A$2:$G$303,SMALL(IF('Problemas em aberto'!$E$2:$E$303=IFERROR(VLOOKUP($F$1,Tabela5[#All],12,0),""),ROW('Problemas em aberto'!$E$2:$E$303)-1),ROW(A3)),6),"") -> #ERROR! | G21: =IFERROR(INDEX('Problemas em aberto'!$A$2:$G$303,SMALL(IF('Problemas em aberto'!$E$2:$E$303=IFERROR(VLOOKUP($F$1,Tabela5[#All],12,0),""),ROW('Problemas em aberto'!$E$2:$E$303)-1),ROW(A3)),4),"") -> #ERROR! | W21: {=IFERROR(INDEX(Pendencias!$A$2:$O$4333,SMALL(IF(Pendencias!$B$2:$B$4333=$F$1,ROW(Pendencias!$B$2:$B$4333)-1),ROW(A21)),1),"")} | X21: {=IFERROR(INDEX(Pendencias!$A$2:$O$4333,SMALL(IF(Pendencias!$B$2:$B$4333=$F$1,ROW(Pendencias!$B$2:$B$4333)-1),ROW(A21)),3),"")} | Y21: {=IFERROR(INDEX(Pendencias!$A$2:$O$4333,SMALL(IF(Pendencias!$B$2:$B$4333=$F$1,ROW(Pendencias!$B$2:$B$4333)-1),ROW(A21)),4),"")} | Z21: {=IFERROR(INDEX(Pendencias!$A$2:$O$4333,SMALL(IF(Pendencias!$B$2:$B$4333=$F$1,ROW(Pendencias!$B$2:$B$4333)-1),ROW(A21)),7),"")} | AA21: {=IF(IFERROR(INDEX(Pendencias!$A$2:$O$4333,SMALL(IF(Pendencias!$B$2:$B$4333=$F$1,ROW(Pendencias!$B$2:$B$4333)-1),ROW(A21)),9),"")=0,"",IFERROR(INDEX(Pendencias!$A$2:$O$4333,SMALL(IF(Pendencias!$B$2:$B$4333=$F$1,ROW(Pendencias!$B$2:$B$4333)-1),ROW(A21)),9),""))}
A22: =IFERROR(INDEX('Problemas em aberto'!$A$2:$G$303,SMALL(IF('Problemas em aberto'!$E$2:$E$303=IFERROR(VLOOKUP($F$1,Tabela5[#All],12,0),""),ROW('Problemas em aberto'!$E$2:$E$303)-1),ROW(A4)),1),"") -> #ERROR! | B22: =IFERROR(INDEX('Problemas em aberto'!$A$2:$G$303,SMALL(IF('Problemas em aberto'!$E$2:$E$303=IFERROR(VLOOKUP($F$1,Tabela5[#All],12,0),""),ROW('Problemas em aberto'!$E$2:$E$303)-1),ROW(A4)),2),"") -> #ERROR! | C22: =IFERROR(INDEX('Problemas em aberto'!$A$2:$G$303,SMALL(IF('Problemas em aberto'!$E$2:$E$303=IFERROR(VLOOKUP($F$1,Tabela5[#All],12,0),""),ROW('Problemas em aberto'!$E$2:$E$303)-1),ROW(A4)),7),"") -> #ERROR! | D22: =IFERROR(INDEX('Problemas em aberto'!$A$2:$G$303,SMALL(IF('Problemas em aberto'!$E$2:$E$303=IFERROR(VLOOKUP($F$1,Tabela5[#All],12,0),""),ROW('Problemas em aberto'!$E$2:$E$303)-1),ROW(A4)),6),"") -> #ERROR! | G22: =IFERROR(INDEX('Problemas em aberto'!$A$2:$G$303,SMALL(IF('Problemas em aberto'!$E$2:$E$303=IFERROR(VLOOKUP($F$1,Tabela5[#All],12,0),""),ROW('Problemas em aberto'!$E$2:$E$303)-1),ROW(A4)),4),"") -> #ERROR! | W22: {=IFERROR(INDEX(Pendencias!$A$2:$O$4333,SMALL(IF(Pendencias!$B$2:$B$4333=$F$1,ROW(Pendencias!$B$2:$B$4333)-1),ROW(A22)),1),"")} | X22: {=IFERROR(INDEX(Pendencias!$A$2:$O$4333,SMALL(IF(Pendencias!$B$2:$B$4333=$F$1,ROW(Pendencias!$B$2:$B$4333)-1),ROW(A22)),3),"")} | Y22: {=IFERROR(INDEX(Pendencias!$A$2:$O$4333,SMALL(IF(Pendencias!$B$2:$B$4333=$F$1,ROW(Pendencias!$B$2:$B$4333)-1),ROW(A22)),4),"")} | Z22: {=IFERROR(INDEX(Pendencias!$A$2:$O$4333,SMALL(IF(Pendencias!$B$2:$B$4333=$F$1,ROW(Pendencias!$B$2:$B$4333)-1),ROW(A22)),7),"")} | AA22: {=IF(IFERROR(INDEX(Pendencias!$A$2:$O$4333,SMALL(IF(Pendencias!$B$2:$B$4333=$F$1,ROW(Pendencias!$B$2:$B$4333)-1),ROW(A22)),9),"")=0,"",IFERROR(INDEX(Pendencias!$A$2:$O$4333,SMALL(IF(Pendencias!$B$2:$B$4333=$F$1,ROW(Pendencias!$B$2:$B$4333)-1),ROW(A22)),9),""))}
A23: =IFERROR(INDEX('Problemas em aberto'!$A$2:$G$303,SMALL(IF('Problemas em aberto'!$E$2:$E$303=IFERROR(VLOOKUP($F$1,Tabela5[#All],12,0),""),ROW('Problemas em aberto'!$E$2:$E$303)-1),ROW(A5)),1),"") -> #ERROR! | B23: =IFERROR(INDEX('Problemas em aberto'!$A$2:$G$303,SMALL(IF('Problemas em aberto'!$E$2:$E$303=IFERROR(VLOOKUP($F$1,Tabela5[#All],12,0),""),ROW('Problemas em aberto'!$E$2:$E$303)-1),ROW(A5)),2),"") -> #ERROR! | C23: =IFERROR(INDEX('Problemas em aberto'!$A$2:$G$303,SMALL(IF('Problemas em aberto'!$E$2:$E$303=IFERROR(VLOOKUP($F$1,Tabela5[#All],12,0),""),ROW('Problemas em aberto'!$E$2:$E$303)-1),ROW(A5)),7),"") -> #ERROR! | D23: =IFERROR(INDEX('Problemas em aberto'!$A$2:$G$303,SMALL(IF('Problemas em aberto'!$E$2:$E$303=IFERROR(VLOOKUP($F$1,Tabela5[#All],12,0),""),ROW('Problemas em aberto'!$E$2:$E$303)-1),ROW(A5)),6),"") -> #ERROR! | G23: =IFERROR(INDEX('Problemas em aberto'!$A$2:$G$303,SMALL(IF('Problemas em aberto'!$E$2:$E$303=IFERROR(VLOOKUP($F$1,Tabela5[#All],12,0),""),ROW('Problemas em aberto'!$E$2:$E$303)-1),ROW(A5)),4),"") -> #ERROR! | W23: {=IFERROR(INDEX(Pendencias!$A$2:$O$4333,SMALL(IF(Pendencias!$B$2:$B$4333=$F$1,ROW(Pendencias!$B$2:$B$4333)-1),ROW(A23)),1),"")} | X23: {=IFERROR(INDEX(Pendencias!$A$2:$O$4333,SMALL(IF(Pendencias!$B$2:$B$4333=$F$1,ROW(Pendencias!$B$2:$B$4333)-1),ROW(A23)),3),"")} | Y23: {=IFERROR(INDEX(Pendencias!$A$2:$O$4333,SMALL(IF(Pendencias!$B$2:$B$4333=$F$1,ROW(Pendencias!$B$2:$B$4333)-1),ROW(A23)),4),"")} | Z23: {=IFERROR(INDEX(Pendencias!$A$2:$O$4333,SMALL(IF(Pendencias!$B$2:$B$4333=$F$1,ROW(Pendencias!$B$2:$B$4333)-1),ROW(A23)),7),"")} | AA23: {=IF(IFERROR(INDEX(Pendencias!$A$2:$O$4333,SMALL(IF(Pendencias!$B$2:$B$4333=$F$1,ROW(Pendencias!$B$2:$B$4333)-1),ROW(A23)),9),"")=0,"",IFERROR(INDEX(Pendencias!$A$2:$O$4333,SMALL(IF(Pendencias!$B$2:$B$4333=$F$1,ROW(Pendencias!$B$2:$B$4333)-1),ROW(A23)),9),""))}
A24: =IFERROR(INDEX('Problemas em aberto'!$A$2:$G$303,SMALL(IF('Problemas em aberto'!$E$2:$E$303=IFERROR(VLOOKUP($F$1,Tabela5[#All],12,0),""),ROW('Problemas em aberto'!$E$2:$E$303)-1),ROW(A6)),1),"") -> #ERROR! | B24: =IFERROR(INDEX('Problemas em aberto'!$A$2:$G$303,SMALL(IF('Problemas em aberto'!$E$2:$E$303=IFERROR(VLOOKUP($F$1,Tabela5[#All],12,0),""),ROW('Problemas em aberto'!$E$2:$E$303)-1),ROW(A6)),2),"") -> #ERROR! | C24: =IFERROR(INDEX('Problemas em aberto'!$A$2:$G$303,SMALL(IF('Problemas em aberto'!$E$2:$E$303=IFERROR(VLOOKUP($F$1,Tabela5[#All],12,0),""),ROW('Problemas em aberto'!$E$2:$E$303)-1),ROW(A6)),7),"") -> #ERROR! | D24: =IFERROR(INDEX('Problemas em aberto'!$A$2:$G$303,SMALL(IF('Problemas em aberto'!$E$2:$E$303=IFERROR(VLOOKUP($F$1,Tabela5[#All],12,0),""),ROW('Problemas em aberto'!$E$2:$E$303)-1),ROW(A6)),6),"") -> #ERROR! | G24: =IFERROR(INDEX('Problemas em aberto'!$A$2:$G$303,SMALL(IF('Problemas em aberto'!$E$2:$E$303=IFERROR(VLOOKUP($F$1,Tabela5[#All],12,0),""),ROW('Problemas em aberto'!$E$2:$E$303)-1),ROW(A6)),4),"") -> #ERROR! | W24: {=IFERROR(INDEX(Pendencias!$A$2:$O$4333,SMALL(IF(Pendencias!$B$2:$B$4333=$F$1,ROW(Pendencias!$B$2:$B$4333)-1),ROW(A24)),1),"")} | X24: {=IFERROR(INDEX(Pendencias!$A$2:$O$4333,SMALL(IF(Pendencias!$B$2:$B$4333=$F$1,ROW(Pendencias!$B$2:$B$4333)-1),ROW(A24)),3),"")} | Y24: {=IFERROR(INDEX(Pendencias!$A$2:$O$4333,SMALL(IF(Pendencias!$B$2:$B$4333=$F$1,ROW(Pendencias!$B$2:$B$4333)-1),ROW(A24)),4),"")} | Z24: {=IFERROR(INDEX(Pendencias!$A$2:$O$4333,SMALL(IF(Pendencias!$B$2:$B$4333=$F$1,ROW(Pendencias!$B$2:$B$4333)-1),ROW(A24)),7),"")} | AA24: {=IF(IFERROR(INDEX(Pendencias!$A$2:$O$4333,SMALL(IF(Pendencias!$B$2:$B$4333=$F$1,ROW(Pendencias!$B$2:$B$4333)-1),ROW(A24)),9),"")=0,"",IFERROR(INDEX(Pendencias!$A$2:$O$4333,SMALL(IF(Pendencias!$B$2:$B$4333=$F$1,ROW(Pendencias!$B$2:$B$4333)-1),ROW(A24)),9),""))}
W25: {=IFERROR(INDEX(Pendencias!$A$2:$O$4333,SMALL(IF(Pendencias!$B$2:$B$4333=$F$1,ROW(Pendencias!$B$2:$B$4333)-1),ROW(A25)),1),"")} | X25: {=IFERROR(INDEX(Pendencias!$A$2:$O$4333,SMALL(IF(Pendencias!$B$2:$B$4333=$F$1,ROW(Pendencias!$B$2:$B$4333)-1),ROW(A25)),3),"")} | Y25: {=IFERROR(INDEX(Pendencias!$A$2:$O$4333,SMALL(IF(Pendencias!$B$2:$B$4333=$F$1,ROW(Pendencias!$B$2:$B$4333)-1),ROW(A25)),4),"")} | Z25: {=IFERROR(INDEX(Pendencias!$A$2:$O$4333,SMALL(IF(Pendencias!$B$2:$B$4333=$F$1,ROW(Pendencias!$B$2:$B$4333)-1),ROW(A25)),7),"")} | AA25: {=IF(IFERROR(INDEX(Pendencias!$A$2:$O$4333,SMALL(IF(Pendencias!$B$2:$B$4333=$F$1,ROW(Pendencias!$B$2:$B$4333)-1),ROW(A25)),9),"")=0,"",IFERROR(INDEX(Pendencias!$A$2:$O$4333,SMALL(IF(Pendencias!$B$2:$B$4333=$F$1,ROW(Pendencias!$B$2:$B$4333)-1),ROW(A25)),9),""))}
A26: Tipo de Manobra (assinale apenas 1) | W26: {=IFERROR(INDEX(Pendencias!$A$2:$O$4333,SMALL(IF(Pendencias!$B$2:$B$4333=$F$1,ROW(Pendencias!$B$2:$B$4333)-1),ROW(A26)),1),"")} | X26: {=IFERROR(INDEX(Pendencias!$A$2:$O$4333,SMALL(IF(Pendencias!$B$2:$B$4333=$F$1,ROW(Pendencias!$B$2:$B$4333)-1),ROW(A26)),3),"")} | Y26: {=IFERROR(INDEX(Pendencias!$A$2:$O$4333,SMALL(IF(Pendencias!$B$2:$B$4333=$F$1,ROW(Pendencias!$B$2:$B$4333)-1),ROW(A26)),4),"")} | Z26: {=IFERROR(INDEX(Pendencias!$A$2:$O$4333,SMALL(IF(Pendencias!$B$2:$B$4333=$F$1,ROW(Pendencias!$B$2:$B$4333)-1),ROW(A26)),7),"")} | AA26: {=IF(IFERROR(INDEX(Pendencias!$A$2:$O$4333,SMALL(IF(Pendencias!$B$2:$B$4333=$F$1,ROW(Pendencias!$B$2:$B$4333)-1),ROW(A26)),9),"")=0,"",IFERROR(INDEX(Pendencias!$A$2:$O$4333,SMALL(IF(Pendencias!$B$2:$B$4333=$F$1,ROW(Pendencias!$B$2:$B$4333)-1),ROW(A26)),9),""))}
A27: Emergencial ( ) | C27: Preventiva ( ) | E27: Instalação ( ) | G27: Desinstalação ( ) | I27: Aferição ( ) | L27: {=IFERROR(INDEX(Pendencias!$A$2:$O$209,SMALL(IF(Pendencias!$B$2:$B$209=$F$1,ROW(Pendencias!$B$2:$B$209)-1),ROW(A32)),1),"")} | O27: {=IFERROR(INDEX(Pendencias!$A$2:$O$209,SMALL(IF(Pendencias!$B$2:$B$209=$F$1,ROW(Pendencias!$B$2:$B$209)-1),ROW(A32)),7),"")} | W27: {=IFERROR(INDEX(Pendencias!$A$2:$O$4333,SMALL(IF(Pendencias!$B$2:$B$4333=$F$1,ROW(Pendencias!$B$2:$B$4333)-1),ROW(A27)),1),"")} | X27: {=IFERROR(INDEX(Pendencias!$A$2:$O$4333,SMALL(IF(Pendencias!$B$2:$B$4333=$F$1,ROW(Pendencias!$B$2:$B$4333)-1),ROW(A27)),3),"")} | Y27: {=IFERROR(INDEX(Pendencias!$A$2:$O$4333,SMALL(IF(Pendencias!$B$2:$B$4333=$F$1,ROW(Pendencias!$B$2:$B$4333)-1),ROW(A27)),4),"")} | Z27: {=IFERROR(INDEX(Pendencias!$A$2:$O$4333,SMALL(IF(Pendencias!$B$2:$B$4333=$F$1,ROW(Pendencias!$B$2:$B$4333)-1),ROW(A27)),7),"")} | AA27: {=IF(IFERROR(INDEX(Pendencias!$A$2:$O$4333,SMALL(IF(Pendencias!$B$2:$B$4333=$F$1,ROW(Pendencias!$B$2:$B$4333)-1),ROW(A27)),9),"")=0,"",IFERROR(INDEX(Pendencias!$A$2:$O$4333,SMALL(IF(Pendencias!$B$2:$B$4333=$F$1,ROW(Pendencias!$B$2:$B$4333)-1),ROW(A27)),9),""))}
A28: Vistoria ( ) | C28: Visita técnica ( ) | E28: Nivelamento Régua( ) | H28: Outro: | L28: {=IFERROR(INDEX(Pendencias!$A$2:$O$209,SMALL(IF(Pendencias!$B$2:$B$209=$F$1,ROW(Pendencias!$B$2:$B$209)-1),ROW(A33)),1),"")} | O28: {=IFERROR(INDEX(Pendencias!$A$2:$O$209,SMALL(IF(Pendencias!$B$2:$B$209=$F$1,ROW(Pendencias!$B$2:$B$209)-1),ROW(A33)),7),"")} | W28: {=IFERROR(INDEX(Pendencias!$A$2:$O$4333,SMALL(IF(Pendencias!$B$2:$B$4333=$F$1,ROW(Pendencias!$B$2:$B$4333)-1),ROW(A28)),1),"")} | X28: {=IFERROR(INDEX(Pendencias!$A$2:$O$4333,SMALL(IF(Pendencias!$B$2:$B$4333=$F$1,ROW(Pendencias!$B$2:$B$4333)-1),ROW(A28)),3),"")} | Y28: {=IFERROR(INDEX(Pendencias!$A$2:$O$4333,SMALL(IF(Pendencias!$B$2:$B$4333=$F$1,ROW(Pendencias!$B$2:$B$4333)-1),ROW(A28)),4),"")} | Z28: {=IFERROR(INDEX(Pendencias!$A$2:$O$4333,SMALL(IF(Pendencias!$B$2:$B$4333=$F$1,ROW(Pendencias!$B$2:$B$4333)-1),ROW(A28)),7),"")} | AA28: {=IF(IFERROR(INDEX(Pendencias!$A$2:$O$4333,SMALL(IF(Pendencias!$B$2:$B$4333=$F$1,ROW(Pendencias!$B$2:$B$4333)-1),ROW(A28)),9),"")=0,"",IFERROR(INDEX(Pendencias!$A$2:$O$4333,SMALL(IF(Pendencias!$B$2:$B$4333=$F$1,ROW(Pendencias!$B$2:$B$4333)-1),ROW(A28)),9),""))}
L29: {=IFERROR(INDEX(Pendencias!$A$2:$O$209,SMALL(IF(Pendencias!$B$2:$B$209=$F$1,ROW(Pendencias!$B$2:$B$209)-1),ROW(A34)),1),"")} | O29: {=IFERROR(INDEX(Pendencias!$A$2:$O$209,SMALL(IF(Pendencias!$B$2:$B$209=$F$1,ROW(Pendencias!$B$2:$B$209)-1),ROW(A34)),7),"")} | W29: {=IFERROR(INDEX(Pendencias!$A$2:$O$4333,SMALL(IF(Pendencias!$B$2:$B$4333=$F$1,ROW(Pendencias!$B$2:$B$4333)-1),ROW(A29)),1),"")} | X29: {=IFERROR(INDEX(Pendencias!$A$2:$O$4333,SMALL(IF(Pendencias!$B$2:$B$4333=$F$1,ROW(Pendencias!$B$2:$B$4333)-1),ROW(A29)),3),"")} | Y29: {=IFERROR(INDEX(Pendencias!$A$2:$O$4333,SMALL(IF(Pendencias!$B$2:$B$4333=$F$1,ROW(Pendencias!$B$2:$B$4333)-1),ROW(A29)),4),"")} | Z29: {=IFERROR(INDEX(Pendencias!$A$2:$O$4333,SMALL(IF(Pendencias!$B$2:$B$4333=$F$1,ROW(Pendencias!$B$2:$B$4333)-1),ROW(A29)),7),"")} | AA29: {=IF(IFERROR(INDEX(Pendencias!$A$2:$O$4333,SMALL(IF(Pendencias!$B$2:$B$4333=$F$1,ROW(Pendencias!$B$2:$B$4333)-1),ROW(A29)),9),"")=0,"",IFERROR(INDEX(Pendencias!$A$2:$O$4333,SMALL(IF(Pendencias!$B$2:$B$4333=$F$1,ROW(Pendencias!$B$2:$B$4333)-1),ROW(A29)),9),""))}
A30: Motivo e Objetivos da Manobra | W30: {=IFERROR(INDEX(Pendencias!$A$2:$O$4333,SMALL(IF(Pendencias!$B$2:$B$4333=$F$1,ROW(Pendencias!$B$2:$B$4333)-1),ROW(A30)),1),"")} | X30: {=IFERROR(INDEX(Pendencias!$A$2:$O$4333,SMALL(IF(Pendencias!$B$2:$B$4333=$F$1,ROW(Pendencias!$B$2:$B$4333)-1),ROW(A30)),3),"")} | Y30: {=IFERROR(INDEX(Pendencias!$A$2:$O$4333,SMALL(IF(Pendencias!$B$2:$B$4333=$F$1,ROW(Pendencias!$B$2:$B$4333)-1),ROW(A30)),4),"")} | Z30: {=IFERROR(INDEX(Pendencias!$A$2:$O$4333,SMALL(IF(Pendencias!$B$2:$B$4333=$F$1,ROW(Pendencias!$B$2:$B$4333)-1),ROW(A30)),7),"")} | AA30: {=IF(IFERROR(INDEX(Pendencias!$A$2:$O$4333,SMALL(IF(Pendencias!$B$2:$B$4333=$F$1,ROW(Pendencias!$B$2:$B$4333)-1),ROW(A30)),9),"")=0,"",IFERROR(INDEX(Pendencias!$A$2:$O$4333,SMALL(IF(Pendencias!$B$2:$B$4333=$F$1,ROW(Pendencias!$B$2:$B$4333)-1),ROW(A30)),9),""))}
A31: Estou indo para realizar manutenção preventiva.. .. | W31: {=IFERROR(INDEX(Pendencias!$A$2:$O$4333,SMALL(IF(Pendencias!$B$2:$B$4333=$F$1,ROW(Pendencias!$B$2:$B$4333)-1),ROW(A31)),1),"")} | X31: {=IFERROR(INDEX(Pendencias!$A$2:$O$4333,SMALL(IF(Pendencias!$B$2:$B$4333=$F$1,ROW(Pendencias!$B$2:$B$4333)-1),ROW(A31)),3),"")} | Y31: {=IFERROR(INDEX(Pendencias!$A$2:$O$4333,SMALL(IF(Pendencias!$B$2:$B$4333=$F$1,ROW(Pendencias!$B$2:$B$4333)-1),ROW(A31)),4),"")} | Z31: {=IFERROR(INDEX(Pendencias!$A$2:$O$4333,SMALL(IF(Pendencias!$B$2:$B$4333=$F$1,ROW(Pendencias!$B$2:$B$4333)-1),ROW(A31)),7),"")} | AA31: {=IF(IFERROR(INDEX(Pendencias!$A$2:$O$4333,SMALL(IF(Pendencias!$B$2:$B$4333=$F$1,ROW(Pendencias!$B$2:$B$4333)-1),ROW(A31)),9),"")=0,"",IFERROR(INDEX(Pendencias!$A$2:$O$4333,SMALL(IF(Pendencias!$B$2:$B$4333=$F$1,ROW(Pendencias!$B$2:$B$4333)-1),ROW(A31)),9),""))}
W32: {=IFERROR(INDEX(Pendencias!$A$2:$O$4333,SMALL(IF(Pendencias!$B$2:$B$4333=$F$1,ROW(Pendencias!$B$2:$B$4333)-1),ROW(A32)),1),"")} | X32: {=IFERROR(INDEX(Pendencias!$A$2:$O$4333,SMALL(IF(Pendencias!$B$2:$B$4333=$F$1,ROW(Pendencias!$B$2:$B$4333)-1),ROW(A32)),3),"")} | Y32: {=IFERROR(INDEX(Pendencias!$A$2:$O$4333,SMALL(IF(Pendencias!$B$2:$B$4333=$F$1,ROW(Pendencias!$B$2:$B$4333)-1),ROW(A32)),4),"")} | Z32: {=IFERROR(INDEX(Pendencias!$A$2:$O$4333,SMALL(IF(Pendencias!$B$2:$B$4333=$F$1,ROW(Pendencias!$B$2:$B$4333)-1),ROW(A32)),7),"")} | AA32: {=IF(IFERROR(INDEX(Pendencias!$A$2:$O$4333,SMALL(IF(Pendencias!$B$2:$B$4333=$F$1,ROW(Pendencias!$B$2:$B$4333)-1),ROW(A32)),9),"")=0,"",IFERROR(INDEX(Pendencias!$A$2:$O$4333,SMALL(IF(Pendencias!$B$2:$B$4333=$F$1,ROW(Pendencias!$B$2:$B$4333)-1),ROW(A32)),9),""))}
A33: Avisos Importantes | W33: {=IFERROR(INDEX(Pendencias!$A$2:$O$4333,SMALL(IF(Pendencias!$B$2:$B$4333=$F$1,ROW(Pendencias!$B$2:$B$4333)-1),ROW(A33)),1),"")} | X33: {=IFERROR(INDEX(Pendencias!$A$2:$O$4333,SMALL(IF(Pendencias!$B$2:$B$4333=$F$1,ROW(Pendencias!$B$2:$B$4333)-1),ROW(A33)),3),"")} | Y33: {=IFERROR(INDEX(Pendencias!$A$2:$O$4333,SMALL(IF(Pendencias!$B$2:$B$4333=$F$1,ROW(Pendencias!$B$2:$B$4333)-1),ROW(A33)),4),"")} | Z33: {=IFERROR(INDEX(Pendencias!$A$2:$O$4333,SMALL(IF(Pendencias!$B$2:$B$4333=$F$1,ROW(Pendencias!$B$2:$B$4333)-1),ROW(A33)),7),"")} | AA33: {=IF(IFERROR(INDEX(Pendencias!$A$2:$O$4333,SMALL(IF(Pendencias!$B$2:$B$4333=$F$1,ROW(Pendencias!$B$2:$B$4333)-1),ROW(A33)),9),"")=0,"",IFERROR(INDEX(Pendencias!$A$2:$O$4333,SMALL(IF(Pendencias!$B$2:$B$4333=$F$1,ROW(Pendencias!$B$2:$B$4333)-1),ROW(A33)),9),""))}
